<mujoco model="right_shadow_hand">
  <compiler angle="radian" meshdir="assets/"/>

  <option impratio="10" cone="elliptic"/>

  <default>
    <default class="right_hand">
      <mesh scale="0.001 0.001 0.001"/>
      <joint armature="0.0002" damping="0.05" frictionloss="0.01"/>
      <general forcerange="-1 1" biastype="affine" biasprm="0 -1"/>
      <default class="wrist">
        <joint damping="0.5"/>
        <default class="wrist_y">
          <joint range="-0.523599 0.174533"/>
          <general ctrlrange="-0.523599 0.174533" forcerange="-10 10" gainprm="10" biasprm="0 -10"/>
        </default>
        <default class="wrist_x">
          <joint range="-0.698132 0.488692"/>
          <general ctrlrange="-0.698132 0.488692" forcerange="-5 5" gainprm="8" biasprm="0 -8"/>
        </default>
      </default>
      <default class="thumb">
        <default class="thbase">
          <joint range="-1.0472 1.0472"/>
          <general ctrlrange="-1.0472 1.0472" forcerange="-3 3" gainprm="0.4" biasprm="0 -0.4"/>
        </default>
        <default class="thproximal">
          <joint range="0 1.22173"/>
          <general ctrlrange="0 1.22173" forcerange="-2 2"/>
        </default>
        <default class="thhub">
          <joint range="-0.20944 0.20944"/>
          <general ctrlrange="-0.20944 0.20944" gainprm="0.5" biasprm="0 -0.5"/>
        </default>
        <default class="thmiddle">
          <joint range="-0.698132 0.698132"/>
          <general ctrlrange="-0.698132 0.698132" gainprm="1.5" biasprm="0 -1.5"/>
        </default>
        <default class="thdistal">
          <joint range="-0.261799 1.5708"/>
          <general ctrlrange="-0.261799 1.5708"/>
        </default>
      </default>
      <default class="metacarpal">
        <joint range="0 0.785398"/>
        <general ctrlrange="0 0.785398"/>
      </default>
      <default class="knuckle">
        <joint range="-0.349066 0.349066"/>
        <general ctrlrange="-0.349066 0.349066"/>
      </default>
      <default class="proximal">
        <joint range="-0.261799 1.5708"/>
        <general ctrlrange="-0.261799 1.5708"/>
      </default>
      <default class="middle_distal">
        <joint range="0 1.5708"/>
        <general ctrlrange="0 3.1415" gainprm="0.5" biasprm="0 -0.5"/>
      </default>
      <default class="plastic">
        <geom solref="0.005" solimp="0.5 0.99 0.0001"/>
        <default class="plastic_visual">
          <geom type="mesh" contype="0" conaffinity="0" group="2" material="black"/>
        </default>
        <default class="plastic_collision">
          <geom group="3"/>
        </default>
      </default>
    </default>
  </default>

  <asset>
    <material name="black" shininess="0.25" rgba="0.16355 0.16355 0.16355 1"/>
    <material name="gray" specular="0" shininess="0.25" rgba="0.80848 0.80848 0.80848 1"/>
    <material name="metallic" specular="0" shininess="0.25" rgba="0.9 0.9 0.9 1"/>
    <mesh name="forearm_0" class="right_hand" file="forearm_0.obj"/>
    <mesh name="forearm_1" class="right_hand" file="forearm_1.obj"/>
    <mesh name="forearm_collision" class="right_hand" file="forearm_collision.obj"/>
    <mesh name="wrist" class="right_hand" file="wrist.obj"/>
    <mesh name="palm" class="right_hand" file="palm.obj"/>
    <mesh name="f_knuckle" class="right_hand" file="f_knuckle.obj"/>
    <mesh name="f_proximal" class="right_hand" file="f_proximal.obj"/>
    <mesh name="f_middle" class="right_hand" file="f_middle.obj"/>
    <mesh name="f_distal_pst" class="right_hand" file="f_distal_pst.obj"/>
    <mesh name="lf_metacarpal" class="right_hand" file="lf_metacarpal.obj"/>
    <mesh name="th_proximal" class="right_hand" file="th_proximal.obj"/>
    <mesh name="th_middle" class="right_hand" file="th_middle.obj"/>
    <mesh name="th_distal_pst" class="right_hand" file="th_distal_pst.obj"/>
  </asset>

  <worldbody>
    <geom name="table" size="0.5 0.5 0.01" type="plane" rgba="0.7 0.7 0.7 1"/>
    <body name="rh_forearm" childclass="right_hand" pos="0 0 0.55" quat="0 1 0 0" gravcomp="1">
      <inertial pos="0 0 0.09" mass="3" diaginertia="0.0138 0.0138 0.00744"/>
      <joint name="slide_x" pos="0 0 0" axis="1 0 0" type="slide" range="-0.3 0.3" armature="0.5" frictionloss="0"/>
      <joint name="slide_y" pos="0 0 0" axis="0 1 0" type="slide" range="-0.3 0.3" armature="0.5" frictionloss="0"/>
      <joint name="slide_z" pos="0 0 0" axis="0 0 1" type="slide" range="-0.15 0.2" armature="0.5" frictionloss="0"/>
      <geom class="plastic_visual" material="gray" mesh="forearm_0"/>
      <geom class="plastic_visual" mesh="forearm_1"/>
      <geom class="plastic_collision" type="mesh" mesh="forearm_collision"/>
      <geom class="plastic_collision" size="0.035 0.035 0.035" pos="0.01 0 0.181" quat="0.380188 0.924909 0 0" type="box"/>
      <body name="rh_wrist" pos="0.01 0 0.21301" quat="0.707107 0 0 0.707107" gravcomp="1">
        <inertial pos="0 0 0.029" quat="0.5 0.5 0.5 0.5" mass="0.1" diaginertia="6.4e-05 4.38e-05 3.5e-05"/>
        <joint name="rh_WRJ2" class="wrist_y" pos="0 0 0" axis="0 1 0"/>
        <geom class="plastic_visual" material="metallic" mesh="wrist"/>
        <geom class="plastic_collision" size="0.0135 0.015" quat="0.499998 0.5 0.5 -0.500002" type="cylinder"/>
        <geom class="plastic_collision" size="0.011 0.005" pos="-0.026 0 0.034" quat="0.707107 0 0.707107 0" type="cylinder"/>
        <geom class="plastic_collision" size="0.011 0.005" pos="0.031 0 0.034" quat="0.707107 0 0.707107 0" type="cylinder"/>
        <geom class="plastic_collision" size="0.0135 0.009 0.005" pos="-0.021 0 0.011" quat="0.923879 0 0.382684 0" type="box"/>
        <geom class="plastic_collision" size="0.0135 0.009 0.005" pos="0.026 0 0.01" quat="0.923879 0 -0.382684 0" type="box"/>
        <body name="rh_palm" pos="0 0 0.034" gravcomp="1">
          <inertial pos="0 0 0.035" quat="0.707107 0 0 0.707107" mass="0.3" diaginertia="0.0005287 0.0003581 0.000191"/>
          <joint name="rh_WRJ1" class="wrist_x" pos="0 0 0" axis="1 0 0"/>
          <geom class="plastic_visual" mesh="palm"/>
          <geom class="plastic_collision" size="0.031 0.0035 0.049" pos="0.011 0.0085 0.038" type="box"/>
          <geom class="plastic_collision" size="0.018 0.0085 0.049" pos="-0.002 -0.0035 0.038" type="box"/>
          <geom class="plastic_collision" size="0.013 0.0085 0.005" pos="0.029 -0.0035 0.082" type="box"/>
          <geom class="plastic_collision" size="0.013 0.007 0.009" pos="0.0265 -0.001 0.07" quat="0.987241 0.0990545 0.0124467 0.124052" type="box"/>
          <geom class="plastic_collision" size="0.0105 0.0135 0.012" pos="0.0315 -0.0085 0.001" type="box"/>
          <geom class="plastic_collision" size="0.011 0.0025 0.015" pos="0.0125 -0.015 0.004" quat="0.971338 0 0 -0.237703" type="box"/>
          <geom class="plastic_collision" size="0.009 0.012 0.002" pos="0.011 0 0.089" type="box"/>
          <geom class="plastic_collision" size="0.01 0.012 0.02" pos="-0.03 0 0.009" type="box"/>
          <site name="grasp_site" pos="0 -0.035 0.09" group="4"/>
          <body name="rh_ffknuckle" pos="0.033 0 0.095" gravcomp="1">
            <inertial pos="0 0 0" quat="0.5 0.5 -0.5 0.5" mass="0.008" diaginertia="3.2e-07 2.6e-07 2.6e-07"/>
            <joint name="rh_FFJ4" class="knuckle" pos="0 0 0" axis="0 -1 0"/>
            <geom class="plastic_visual" pos="0 0 0.0005" material="metallic" mesh="f_knuckle"/>
            <geom class="plastic_collision" size="0.009 0.009" quat="0.707107 0 0.707107 0" type="cylinder"/>
            <body name="rh_ffproximal" gravcomp="1">
              <inertial pos="0 0 0.0225" quat="0.707107 0 0 0.707107" mass="0.03" diaginertia="1e-05 9.8e-06 1.8e-06"/>
              <joint name="rh_FFJ3" class="proximal" pos="0 0 0" axis="1 0 0"/>
              <geom class="plastic_visual" mesh="f_proximal"/>
              <geom class="plastic_collision" size="0.009 0.02" pos="0 0 0.025" type="capsule"/>
              <body name="rh_ffmiddle" pos="0 0 0.045" gravcomp="1">
                <inertial pos="0 0 0.0125" quat="0.707107 0 0 0.707107" mass="0.017" diaginertia="2.7e-06 2.6e-06 8.7e-07"/>
                <joint name="rh_FFJ2" class="middle_distal" pos="0 0 0" axis="1 0 0"/>
                <geom class="plastic_visual" mesh="f_middle"/>
                <geom class="plastic_collision" size="0.009 0.0125" pos="0 0 0.0125" type="capsule"/>
                <body name="rh_ffdistal" pos="0 0 0.025" gravcomp="1">
                  <inertial pos="0 0 0.0130769" quat="0.707107 0 0 0.707107" mass="0.013" diaginertia="1.28092e-06 1.12092e-06 5.3e-07"/>
                  <joint name="rh_FFJ1" class="middle_distal" pos="0 0 0" axis="1 0 0"/>
                  <geom class="plastic_visual" mesh="f_distal_pst"/>
                  <geom class="plastic_collision" type="mesh" mesh="f_distal_pst"/>
                </body>
              </body>
            </body>
          </body>
          <body name="rh_mfknuckle" pos="0.011 0 0.099" gravcomp="1">
            <inertial pos="0 0 0" quat="0.5 0.5 -0.5 0.5" mass="0.008" diaginertia="3.2e-07 2.6e-07 2.6e-07"/>
            <joint name="rh_MFJ4" class="knuckle" pos="0 0 0" axis="0 -1 0"/>
            <geom class="plastic_visual" pos="0 0 0.0005" material="metallic" mesh="f_knuckle"/>
            <geom class="plastic_collision" size="0.009 0.009" quat="0.707107 0 0.707107 0" type="cylinder"/>
            <body name="rh_mfproximal" gravcomp="1">
              <inertial pos="0 0 0.0225" quat="0.707107 0 0 0.707107" mass="0.03" diaginertia="1e-05 9.8e-06 1.8e-06"/>
              <joint name="rh_MFJ3" class="proximal" pos="0 0 0" axis="1 0 0"/>
              <geom class="plastic_visual" mesh="f_proximal"/>
              <geom class="plastic_collision" size="0.009 0.02" pos="0 0 0.025" type="capsule"/>
              <body name="rh_mfmiddle" pos="0 0 0.045" gravcomp="1">
                <inertial pos="0 0 0.0125" quat="0.707107 0 0 0.707107" mass="0.017" diaginertia="2.7e-06 2.6e-06 8.7e-07"/>
                <joint name="rh_MFJ2" class="middle_distal" pos="0 0 0" axis="1 0 0"/>
                <geom class="plastic_visual" mesh="f_middle"/>
                <geom class="plastic_collision" size="0.009 0.0125" pos="0 0 0.0125" type="capsule"/>
                <body name="rh_mfdistal" pos="0 0 0.025" gravcomp="1">
                  <inertial pos="0 0 0.0130769" quat="0.707107 0 0 0.707107" mass="0.013" diaginertia="1.28092e-06 1.12092e-06 5.3e-07"/>
                  <joint name="rh_MFJ1" class="middle_distal" pos="0 0 0" axis="1 0 0"/>
                  <geom class="plastic_visual" mesh="f_distal_pst"/>
                  <geom class="plastic_collision" type="mesh" mesh="f_distal_pst"/>
                </body>
              </body>
            </body>
          </body>
          <body name="rh_rfknuckle" pos="-0.011 0 0.095" gravcomp="1">
            <inertial pos="0 0 0" quat="0.5 0.5 -0.5 0.5" mass="0.008" diaginertia="3.2e-07 2.6e-07 2.6e-07"/>
            <joint name="rh_RFJ4" class="knuckle" pos="0 0 0" axis="0 1 0"/>
            <geom class="plastic_visual" pos="0 0 0.0005" material="metallic" mesh="f_knuckle"/>
            <geom class="plastic_collision" size="0.009 0.009" quat="0.707107 0 0.707107 0" type="cylinder"/>
            <body name="rh_rfproximal" gravcomp="1">
              <inertial pos="0 0 0.0225" quat="0.707107 0 0 0.707107" mass="0.03" diaginertia="1e-05 9.8e-06 1.8e-06"/>
              <joint name="rh_RFJ3" class="proximal" pos="0 0 0" axis="1 0 0"/>
              <geom class="plastic_visual" mesh="f_proximal"/>
              <geom class="plastic_collision" size="0.009 0.02" pos="0 0 0.025" type="capsule"/>
              <body name="rh_rfmiddle" pos="0 0 0.045" gravcomp="1">
                <inertial pos="0 0 0.0125" quat="0.707107 0 0 0.707107" mass="0.017" diaginertia="2.7e-06 2.6e-06 8.7e-07"/>
                <joint name="rh_RFJ2" class="middle_distal" pos="0 0 0" axis="1 0 0"/>
                <geom class="plastic_visual" mesh="f_middle"/>
                <geom class="plastic_collision" size="0.009 0.0125" pos="0 0 0.0125" type="capsule"/>
                <body name="rh_rfdistal" pos="0 0 0.025" gravcomp="1">
                  <inertial pos="0 0 0.0130769" quat="0.707107 0 0 0.707107" mass="0.013" diaginertia="1.28092e-06 1.12092e-06 5.3e-07"/>
                  <joint name="rh_RFJ1" class="middle_distal" pos="0 0 0" axis="1 0 0"/>
                  <geom class="plastic_visual" mesh="f_distal_pst"/>
                  <geom class="plastic_collision" type="mesh" mesh="f_distal_pst"/>
                </body>
              </body>
            </body>
          </body>
          <body name="rh_lfmetacarpal" pos="-0.033 0 0.02071" gravcomp="1">
            <inertial pos="0 0 0.04" quat="0.707107 0 0 0.707107" mass="0.03" diaginertia="1.638e-05 1.45e-05 4.272e-06"/>
            <joint name="rh_LFJ5" class="metacarpal" pos="0 0 0" axis="0.573576 0 0.819152"/>
            <geom class="plastic_visual" mesh="lf_metacarpal"/>
            <geom class="plastic_collision" size="0.011 0.012 0.025" pos="0.002 0 0.033" type="box"/>
            <body name="rh_lfknuckle" pos="0 0 0.06579" gravcomp="1">
              <inertial pos="0 0 0" quat="0.5 0.5 -0.5 0.5" mass="0.008" diaginertia="3.2e-07 2.6e-07 2.6e-07"/>
              <joint name="rh_LFJ4" class="knuckle" pos="0 0 0" axis="0 1 0"/>
              <geom class="plastic_visual" pos="0 0 0.0005" material="metallic" mesh="f_knuckle"/>
              <geom class="plastic_collision" size="0.009 0.009" quat="0.707107 0 0.707107 0" type="cylinder"/>
              <body name="rh_lfproximal" gravcomp="1">
                <inertial pos="0 0 0.0225" quat="0.707107 0 0 0.707107" mass="0.03" diaginertia="1e-05 9.8e-06 1.8e-06"/>
                <joint name="rh_LFJ3" class="proximal" pos="0 0 0" axis="1 0 0"/>
                <geom class="plastic_visual" mesh="f_proximal"/>
                <geom class="plastic_collision" size="0.009 0.02" pos="0 0 0.025" type="capsule"/>
                <body name="rh_lfmiddle" pos="0 0 0.045" gravcomp="1">
                  <inertial pos="0 0 0.0125" quat="0.707107 0 0 0.707107" mass="0.017" diaginertia="2.7e-06 2.6e-06 8.7e-07"/>
                  <joint name="rh_LFJ2" class="middle_distal" pos="0 0 0" axis="1 0 0"/>
                  <geom class="plastic_visual" mesh="f_middle"/>
                  <geom class="plastic_collision" size="0.009 0.0125" pos="0 0 0.0125" type="capsule"/>
                  <body name="rh_lfdistal" pos="0 0 0.025" gravcomp="1">
                    <inertial pos="0 0 0.0130769" quat="0.707107 0 0 0.707107" mass="0.013" diaginertia="1.28092e-06 1.12092e-06 5.3e-07"/>
                    <joint name="rh_LFJ1" class="middle_distal" pos="0 0 0" axis="1 0 0"/>
                    <geom class="plastic_visual" mesh="f_distal_pst"/>
                    <geom class="plastic_collision" type="mesh" mesh="f_distal_pst"/>
                  </body>
                </body>
              </body>
            </body>
          </body>
          <body name="rh_thbase" pos="0.034 -0.00858 0.029" quat="0.92388 0 0.382683 0" gravcomp="1">
            <inertial pos="0 0 0" mass="0.01" diaginertia="1.6e-07 1.6e-07 1.6e-07"/>
            <joint name="rh_THJ5" class="thbase" pos="0 0 0" axis="0 0 -1"/>
            <geom class="plastic_collision" size="0.013"/>
            <body name="rh_thproximal" gravcomp="1">
              <inertial pos="0 0 0.019" mass="0.04" diaginertia="1.36e-05 1.36e-05 3.13e-06"/>
              <joint name="rh_THJ4" class="thproximal" pos="0 0 0" axis="1 0 0"/>
              <geom class="plastic_visual" mesh="th_proximal"/>
              <geom class="plastic_collision" size="0.0105 0.009" pos="0 0 0.02" type="capsule"/>
              <body name="rh_thhub" pos="0 0 0.038" gravcomp="1">
                <inertial pos="0 0 0" mass="0.005" diaginertia="1e-06 1e-06 3e-07"/>
                <joint name="rh_THJ3" class="thhub" pos="0 0 0" axis="1 0 0"/>
                <geom class="plastic_collision" size="0.011"/>
                <body name="rh_thmiddle" gravcomp="1">
                  <inertial pos="0 0 0.016" mass="0.02" diaginertia="5.1e-06 5.1e-06 1.21e-06"/>
                  <joint name="rh_THJ2" class="thmiddle" pos="0 0 0" axis="0 -1 0"/>
                  <geom class="plastic_visual" mesh="th_middle"/>
                  <geom class="plastic_collision" size="0.009 0.009" pos="0 0 0.012" type="capsule"/>
                  <geom class="plastic_collision" size="0.01" pos="0 0 0.03"/>
                  <body name="rh_thdistal" pos="0 0 0.032" quat="0.707107 0 0 -0.707107" gravcomp="1">
                    <inertial pos="0 0 0.0145588" quat="0.707107 0 0 0.707107" mass="0.017" diaginertia="2.37794e-06 2.27794e-06 1e-06"/>
                    <joint name="rh_THJ1" class="thdistal" pos="0 0 0" axis="1 0 0"/>
                    <geom class="plastic_visual" mesh="th_distal_pst"/>
                    <geom class="plastic_collision" type="mesh" mesh="th_distal_pst"/>
                  </body>
                </body>
              </body>
            </body>
          </body>
        </body>
      </body>
    </body>
    <body name="object" pos="0 0 0.025">
      <joint type="free"/>
      <geom name="cube" size="0.025 0.025 0.025" type="box" condim="4" friction="1 0.05 0.001" mass="0.05" rgba="0.8 0.2 0.2 1"/>
    </body>
  </worldbody>

  <contact>
    <exclude body1="rh_forearm" body2="rh_wrist"/>
    <exclude body1="rh_thproximal" body2="rh_thmiddle"/>
  </contact>

  <tendon>
    <fixed name="rh_FFJ0">
      <joint joint="rh_FFJ2" coef="1"/>
      <joint joint="rh_FFJ1" coef="1"/>
    </fixed>
    <fixed name="rh_MFJ0">
      <joint joint="rh_MFJ2" coef="1"/>
      <joint joint="rh_MFJ1" coef="1"/>
    </fixed>
    <fixed name="rh_RFJ0">
      <joint joint="rh_RFJ2" coef="1"/>
      <joint joint="rh_RFJ1" coef="1"/>
    </fixed>
    <fixed name="rh_LFJ0">
      <joint joint="rh_LFJ2" coef="1"/>
      <joint joint="rh_LFJ1" coef="1"/>
    </fixed>
  </tendon>

  <actuator>
    <general name="rh_A_WRJ2" class="wrist_y" joint="rh_WRJ2"/>
    <general name="rh_A_WRJ1" class="wrist_x" joint="rh_WRJ1"/>
    <general name="rh_A_THJ5" class="thbase" joint="rh_THJ5"/>
    <general name="rh_A_THJ4" class="thproximal" joint="rh_THJ4"/>
    <general name="rh_A_THJ3" class="thhub" joint="rh_THJ3"/>
    <general name="rh_A_THJ2" class="thmiddle" joint="rh_THJ2"/>
    <general name="rh_A_THJ1" class="thdistal" joint="rh_THJ1"/>
    <general name="rh_A_FFJ4" class="knuckle" joint="rh_FFJ4"/>
    <general name="rh_A_FFJ3" class="proximal" joint="rh_FFJ3"/>
    <general name="rh_A_FFJ0" class="middle_distal" tendon="rh_FFJ0"/>
    <general name="rh_A_MFJ4" class="knuckle" joint="rh_MFJ4"/>
    <general name="rh_A_MFJ3" class="proximal" joint="rh_MFJ3"/>
    <general name="rh_A_MFJ0" class="middle_distal" tendon="rh_MFJ0"/>
    <general name="rh_A_RFJ4" class="knuckle" joint="rh_RFJ4"/>
    <general name="rh_A_RFJ3" class="proximal" joint="rh_RFJ3"/>
    <general name="rh_A_RFJ0" class="middle_distal" tendon="rh_RFJ0"/>
    <general name="rh_A_LFJ5" class="metacarpal" joint="rh_LFJ5"/>
    <general name="rh_A_LFJ4" class="knuckle" joint="rh_LFJ4"/>
    <general name="rh_A_LFJ3" class="proximal" joint="rh_LFJ3"/>
    <general name="rh_A_LFJ0" class="middle_distal" tendon="rh_LFJ0"/>
    <general name="base_x" joint="slide_x" ctrllimited="true" ctrlrange="-0.3 0.3" forcelimited="true" forcerange="-50 50" biastype="affine" gainprm="500" biasprm="0 -500"/>
    <general name="base_y" joint="slide_y" ctrllimited="true" ctrlrange="-0.3 0.3" forcelimited="true" forcerange="-50 50" biastype="affine" gainprm="500" biasprm="0 -500"/>
    <general name="base_z" joint="slide_z" ctrllimited="true" ctrlrange="-0.15 0.2" forcelimited="true" forcerange="-50 50" biastype="affine" gainprm="1000" biasprm="0 -1000"/>
  </actuator>
</mujoco>
